Workbook
Name d_clk: Data!$G:$G
Name d_conv: Data!$K:$K
Name d_ctry: Data!$E:$E
Name d_date: Data!$A:$A
Name d_imp: Data!$F:$F
Name d_ind: Data!$D:$D
Name d_plat: Data!$B:$B
Name d_rev: Data!$M:$M
Name d_spend: Data!$J:$J
Name d_type: Data!$C:$C

Sheet Dashboard
B2: GLOBAL ADS PERFORMANCE DASHBOARD | U2: ="Period in view"&CHAR(10)&Calc!$B$18 -> Period in view Jan 1, 2024 - Dec 31, 2024 | AC2: Analyze performance across Google Ads, Meta Ads, and TikTok Ads to drive better marketing decisions.
B3: Marketing Analytics | Jan-Dec 2024
C6: 💰 | E6: TOTAL AD SPEND | K6: 📈 | M6: TOTAL REVENUE | S6: 🎯 | U6: OVERALL ROAS | AA6: 👥 | AC6: OVERALL CPA | AI6: ✅ | AK6: CONVERSIONS | AP6: CTR by Campaign Type
E7: =Calc!$B$21 -> 11108749 | M7: =Calc!$B$22 -> 54183331 | U7: =Calc!$B$26 -> 4.8775366 | AC7: =Calc!$B$27 -> 33.991252 | AK7: =Calc!$B$23 -> 326812
E8: =Calc!$E$21 -> -0.027794041 | G8: =Calc!$B$17 -> H2 vs H1 | M8: =Calc!$E$22 -> -0.0023304819 | O8: =Calc!$B$17 -> H2 vs H1 | U8: =Calc!$E$26 -> 0.026191528 | W8: =Calc!$B$17 -> H2 vs H1 | AC8: =Calc!$E$27 -> -0.021059609 | AE8: =Calc!$B$17 -> H2 vs H1 | AK8: =Calc!$E$23 -> -0.0068793072 | AM8: =Calc!$B$17 -> H2 vs H1
B10: IMPRESSIONS | F10: =Calc!$B$24 -> 185254234 | J10: CLICKS | N10: =Calc!$B$25 -> 7132816 | R10: CTR | V10: =Calc!$B$28 -> 0.03850285 | Z10: CPC | AD10: =Calc!$B$29 -> 1.5574142 | AH10: CONVERSION RATE | AL10: =Calc!$B$30 -> 0.045818089
B12: ▼ FILTERS click a cell, pick from the list
F13: Date Range ▾ | M13: Platform ▾ | T13: Industry ▾ | AA13: Country ▾ | AH13: Campaign Type ▾
F14: All Periods | M14: All Platforms | T14: All Industries | AA14: All Countries | AH14: All Campaign Types
B17: Monthly Spend vs Revenue (all months · other filters apply) | V17: ROAS by Platform | AF17: Ad Spend Share by Platform | AP17: Campaign Performance Detail (Top 10 segments by revenue · follows the filters)
AP18: # | AQ18: Platform | AT18: Campaign Type | AW18: Industry | AZ18: Country | BB18: Ad Spend | BD18: Conversions | BG18: Revenue | BI18: ROAS | BK18: CPA
AP19: =IF(Calc!$K$95="","",1) -> 1 | AQ19: =Calc!$K$95 -> Google Ads | AT19: =Calc!$L$95 -> Shopping | AW19: =Calc!$M$95 -> Fintech | AZ19: =Calc!$N$95 -> Australia | BB19: =Calc!$O$95 -> 135409.45 | BD19: =Calc!$P$95 -> 3128 | BG19: =Calc!$Q$95 -> 614423.03 | BI19: =Calc!$R$95 -> 4.5375196 | BK19: =Calc!$S$95 -> 43.289466
AP20: =IF(Calc!$K$96="","",2) -> 2 | AQ20: =Calc!$K$96 -> TikTok Ads | AT20: =Calc!$L$96 -> Video | AW20: =Calc!$M$96 -> EdTech | AZ20: =Calc!$N$96 -> India | BB20: =Calc!$O$96 -> 58952.21 | BD20: =Calc!$P$96 -> 2630 | BG20: =Calc!$Q$96 -> 517884.41 | BI20: =Calc!$R$96 -> 8.7848176 | BK20: =Calc!$S$96 -> 22.415289
AP21: =IF(Calc!$K$97="","",3) -> 3 | AQ21: =Calc!$K$97 -> TikTok Ads | AT21: =Calc!$L$97 -> Display | AW21: =Calc!$M$97 -> Healthcare | AZ21: =Calc!$N$97 -> UK | BB21: =Calc!$O$97 -> 37769.39 | BD21: =Calc!$P$97 -> 2246 | BG21: =Calc!$Q$97 -> 490495.75 | BI21: =Calc!$R$97 -> 12.986594 | BK21: =Calc!$S$97 -> 16.816291
AP22: =IF(Calc!$K$98="","",4) -> 4 | AQ22: =Calc!$K$98 -> Google Ads | AT22: =Calc!$L$98 -> Shopping | AW22: =Calc!$M$98 -> SaaS | AZ22: =Calc!$N$98 -> UAE | BB22: =Calc!$O$98 -> 97854.09 | BD22: =Calc!$P$98 -> 2161 | BG22: =Calc!$Q$98 -> 457394.25 | BI22: =Calc!$R$98 -> 4.6742476 | BK22: =Calc!$S$98 -> 45.281856
AP23: =IF(Calc!$K$99="","",5) -> 5 | AQ23: =Calc!$K$99 -> Google Ads | AT23: =Calc!$L$99 -> Video | AW23: =Calc!$M$99 -> SaaS | AZ23: =Calc!$N$99 -> Canada | BB23: =Calc!$O$99 -> 135248.7 | BD23: =Calc!$P$99 -> 2627 | BG23: =Calc!$Q$99 -> 450585.57 | BI23: =Calc!$R$99 -> 3.3315335 | BK23: =Calc!$S$99 -> 51.484088
AP24: =IF(Calc!$K$100="","",6) -> 6 | AQ24: =Calc!$K$100 -> TikTok Ads | AT24: =Calc!$L$100 -> Shopping | AW24: =Calc!$M$100 -> SaaS | AZ24: =Calc!$N$100 -> India | BB24: =Calc!$O$100 -> 47080.55 | BD24: =Calc!$P$100 -> 2630 | BG24: =Calc!$Q$100 -> 448558.22 | BI24: =Calc!$R$100 -> 9.5274635 | BK24: =Calc!$S$100 -> 17.90135
AP25: =IF(Calc!$K$101="","",7) -> 7 | AQ25: =Calc!$K$101 -> TikTok Ads | AT25: =Calc!$L$101 -> Search | AW25: =Calc!$M$101 -> E-commerce | AZ25: =Calc!$N$101 -> Canada | BB25: =Calc!$O$101 -> 48942 | BD25: =Calc!$P$101 -> 2157 | BG25: =Calc!$Q$101 -> 447198.87 | BI25: =Calc!$R$101 -> 9.1373232 | BK25: =Calc!$S$101 -> 22.689847
AP26: =IF(Calc!$K$102="","",8) -> 8 | AQ26: =Calc!$K$102 -> TikTok Ads | AT26: =Calc!$L$102 -> Shopping | AW26: =Calc!$M$102 -> Healthcare | AZ26: =Calc!$N$102 -> Australia | BB26: =Calc!$O$102 -> 57265.14 | BD26: =Calc!$P$102 -> 2671 | BG26: =Calc!$Q$102 -> 438104.1 | BI26: =Calc!$R$102 -> 7.6504502 | BK26: =Calc!$S$102 -> 21.439588
AP27: =IF(Calc!$K$103="","",9) -> 9 | AQ27: =Calc!$K$103 -> TikTok Ads | AT27: =Calc!$L$103 -> Search | AW27: =Calc!$M$103 -> EdTech | AZ27: =Calc!$N$103 -> India | BB27: =Calc!$O$103 -> 45802.07 | BD27: =Calc!$P$103 -> 2125 | BG27: =Calc!$Q$103 -> 428403.47 | BI27: =Calc!$R$103 -> 9.3533648 | BK27: =Calc!$S$103 -> 21.553915
AP28: =IF(Calc!$K$104="","",10) -> 10 | AQ28: =Calc!$K$104 -> Google Ads | AT28: =Calc!$L$104 -> Search | AW28: =Calc!$M$104 -> E-commerce | AZ28: =Calc!$N$104 -> USA | BB28: =Calc!$O$104 -> 70377.18 | BD28: =Calc!$P$104 -> 2467 | BG28: =Calc!$Q$104 -> 421658.46 | BI28: =Calc!$R$104 -> 5.9914089 | BK28: =Calc!$S$104 -> 28.527434
AP29: ="Green = better than the average of the current view (ROAS ≥ "&ROUND(Calc!$B$26,2)&"x, CPA ≤ $"&ROUND(Calc!$B$27,2)&"), red = worse. ROAS = Revenue ÷ Ad Spend · CPA = Ad Spend ÷ Conversions · CTR = Clicks ÷ Impressions. Currency assumed USD. Source: Data sheet ("&(COUNTA(Data!A:A)-1)&" records)." -> Green = better than the average of the current view (ROAS ≥ 4.88x, CPA ≤ $33.99), red = worse. ROAS = Revenue ÷ Ad Spend · CPA = Ad Spend ÷ Conversions · CTR = Clicks ÷ Impressions. Currency assumed USD. Source: Data sheet (1800 records).
B34: ROAS by Industry | V34: CPA by Country | AP34: 📋 KEY FINDINGS & ACTIONS
AP35: 1 | AQ35: Finding 1 · Platform efficiency
AQ36: =Calc!$B$87 -> Best platform: TikTok Ads returns 7.62x ROAS vs 3.47x on Google Ads - a gap of 4.15x revenue per $1 of spend.
AP39: 2 | AQ39: Finding 2 · Industry & country
AQ40: =Calc!$B$90 -> SaaS leads industries at 5.04x ROAS, while Fintech trails at 4.48x. USA has the highest CPA ($36.01) vs $30.76 in India.
AP43: 3 | AQ43: Recommended action
AQ44: =Calc!$B$91 -> Shift budget from Google Ads toward TikTok Ads. Audit targeting in USA to cut CPA. Scale Search campaigns (highest CTR at 3.99%).

Sheet Data
A1: date | B1: platform | C1: campaign_type | D1: industry | E1: country | F1: impressions | G1: clicks | H1: CTR | I1: CPC | J1: ad_spend | K1: conversions | L1: CPA | M1: revenue | N1: ROAS
A2: 45312 | B2: Google Ads | C2: Search | D2: Fintech | E2: UAE | F2: 59886 | G2: 2113 | H2: 0.0353 | I2: 1.26 | J2: 2662.38 | K2: 159 | L2: 16.74 | M2: 4803.43 | N2: 1.8
A3: 45313 | B3: TikTok Ads | C3: Search | D3: EdTech | E3: UK | F3: 135608 | G3: 5220 | H3: 0.0385 | I3: 1.18 | J3: 6159.6 | K3: 411 | L3: 14.99 | M3: 64126.68 | N3: 10.41
A4: 45458 | B4: TikTok Ads | C4: Video | D4: Healthcare | E4: USA | F4: 92313 | G4: 5991 | H4: 0.0649 | I4: 0.85 | J4: 5092.35 | K4: 267 | L4: 19.07 | M4: 10489.07 | N4: 2.06
A5: 45293 | B5: TikTok Ads | C5: Shopping | D5: SaaS | E5: Germany | F5: 83953 | G5: 5935 | H5: 0.0707 | I5: 1.32 | J5: 7834.2 | K5: 296 | L5: 26.47 | M5: 50505.07 | N5: 6.45
A6: 45344 | B6: TikTok Ads | C6: Search | D6: Healthcare | E6: UK | F6: 91807 | G6: 4489 | H6: 0.0489 | I6: 1.93 | J6: 8663.77 | K6: 107 | L6: 80.97 | M6: 3369.53 | N6: 0.39
A7: 45580 | B7: TikTok Ads | C7: Search | D7: Fintech | E7: Canada | F7: 17666 | G7: 724 | H7: 0.041 | I7: 0.37 | J7: 267.88 | K7: 23 | L7: 11.65 | M7: 5220.85 | N7: 19.49
A8: 45518 | B8: Meta Ads | C8: Video | D8: Fintech | E8: USA | F8: 118252 | G8: 3748 | H8: 0.0317 | I8: 0.42 | J8: 1574.16 | K8: 152 | L8: 10.36 | M8: 12838.56 | N8: 8.16
A9: 45387 | B9: TikTok Ads | C9: Search | D9: EdTech | E9: UAE | F9: 92939 | G9: 5176 | H9: 0.0557 | I9: 0.66 | J9: 3416.16 | K9: 388 | L9: 8.8 | M9: 96298.69 | N9: 28.19
A10: 45399 | B10: Meta Ads | C10: Display | D10: EdTech | E10: Germany | F10: 30939 | G10: 937 | H10: 0.0303 | I10: 0.59 | J10: 552.83 | K10: 63 | L10: 8.78 | M10: 16531.03 | N10: 29.9
A11: 45609 | B11: Google Ads | C11: Shopping | D11: Fintech | E11: USA | F11: 8748 | G11: 362 | H11: 0.0414 | I11: 1.21 | J11: 438.02 | K11: 10 | L11: 43.8 | M11: 966.57 | N11: 2.21
A12: 45404 | B12: Meta Ads | C12: Video | D12: E-commerce | E12: UAE | F12: 98264 | G12: 3144 | H12: 0.032 | I12: 1.56 | J12: 4904.64 | K12: 129 | L12: 38.02 | M12: 23127.27 | N12: 4.72
A13: 45546 | B13: Meta Ads | C13: Video | D13: Fintech | E13: Canada | F13: 173229 | G13: 5092 | H13: 0.0294 | I13: 1.72 | J13: 8758.24 | K13: 65 | L13: 134.74 | M13: 12320.17 | N13: 1.41
... A1801: 45320 | B1801: Meta Ads | C1801: Display | D1801: EdTech | E1801: UK | F1801: 77447 | G1801: 906 | H1801: 0.0117 | I1801: 1.15 | J1801: 1041.9 | K1801: 29 | L1801: 35.93 | M1801: 8284.13 | N1801: 7.95

Sheet Calc
A1: Calculation sheet - feeds the Dashboard (do not edit; change filters on the Dashboard)
A3: Date Range | B3: =Dashboard!$F$14 -> All Periods
A4: Platform | B4: =Dashboard!$M$14 -> All Platforms | C4: =IF($B4="All Platforms","*",$B4) -> *
A5: Industry | B5: =Dashboard!$T$14 -> All Industries | C5: =IF($B5="All Industries","*",$B5) -> *
A6: Country | B6: =Dashboard!$AA$14 -> All Countries | C6: =IF($B6="All Countries","*",$B6) -> *
A7: Campaign Type | B7: =Dashboard!$AH$14 -> All Campaign Types | C7: =IF($B7="All Campaign Types","*",$B7) -> *
A9: Start date | B9: =INDEX(Lists!$B$4:$B$22,MATCH($B$3,Lists!$A$4:$A$22,0)) -> 45292
A10: End date | B10: =INDEX(Lists!$C$4:$C$22,MATCH($B$3,Lists!$A$4:$A$22,0)) -> 45657
A11: Months in range | B11: =(YEAR(B10)-YEAR(B9))*12+MONTH(B10)-MONTH(B9)+1 -> 12
A12: Compare: current start | B12: =IF($B$3="All Periods",DATE(Lists!$B$1,7,1),$B$9) -> 45474
A13: Compare: current end | B13: =IF($B$3="All Periods",DATE(Lists!$B$1,12,31),$B$10) -> 45657
A14: Compare: previous start | B14: =IF($B$3="All Periods",DATE(Lists!$B$1,1,1),EDATE($B$9,-$B$11)) -> 45292
A15: Compare: previous end | B15: =IF($B$3="All Periods",DATE(Lists!$B$1,6,30),$B$9-1) -> 45473
A16: Previous period valid? | B16: =IF($B$3="All Periods",1,IF($B$14>=DATE(Lists!$B$1,1,1),1,0)) -> 1
A17: Comparison label | B17: =IF($B$3="All Periods","H2 vs H1",IF($B$16=1,"vs previous period","no prior period")) -> H2 vs H1
A18: Period text | B18: =INDEX(Lists!$M$4:$M$15,MONTH(B9))&" "&DAY(B9)&", "&YEAR(B9)&" - "&INDEX(Lists!$M$4:$M$15,MONTH(B10))&" "&DAY(B10)&", "&YEAR(B10) -> Jan 1, 2024 - Dec 31, 2024
A20: Metric | B20: Selected | C20: Compare current | D20: Compare previous | E20: Delta % | F20: Signal
A21: Ad Spend | B21: =SUMIFS(d_spend,d_date,">="&$B$9,d_date,"<="&$B$10,d_plat,$C$4,d_type,$C$7,d_ind,$C$5,d_ctry,$C$6) -> 11108749 | C21: =SUMIFS(d_spend,d_date,">="&$B$12,d_date,"<="&$B$13,d_plat,$C$4,d_type,$C$7,d_ind,$C$5,d_ctry,$C$6) -> 5476097.5 | D21: =SUMIFS(d_spend,d_date,">="&$B$14,d_date,"<="&$B$15,d_plat,$C$4,d_type,$C$7,d_ind,$C$5,d_ctry,$C$6) -> 5632651.6 | E21: =IF($B$16=1,IF(D21=0,"n/a",C21/D21-1),"n/a") -> -0.027794041 | F21: 0
A22: Revenue | B22: =SUMIFS(d_rev,d_date,">="&$B$9,d_date,"<="&$B$10,d_plat,$C$4,d_type,$C$7,d_ind,$C$5,d_ctry,$C$6) -> 54183331 | C22: =SUMIFS(d_rev,d_date,">="&$B$12,d_date,"<="&$B$13,d_plat,$C$4,d_type,$C$7,d_ind,$C$5,d_ctry,$C$6) -> 27060060 | D22: =SUMIFS(d_rev,d_date,">="&$B$14,d_date,"<="&$B$15,d_plat,$C$4,d_type,$C$7,d_ind,$C$5,d_ctry,$C$6) -> 27123271 | E22: =IF($B$16=1,IF(D22=0,"n/a",C22/D22-1),"n/a") -> -0.0023304819 | F22: =IF(ISNUMBER(E22),IF(E22>=0,1,-1),0) -> -1
A23: Conversions | B23: =SUMIFS(d_conv,d_date,">="&$B$9,d_date,"<="&$B$10,d_plat,$C$4,d_type,$C$7,d_ind,$C$5,d_ctry,$C$6) -> 326812 | C23: =SUMIFS(d_conv,d_date,">="&$B$12,d_date,"<="&$B$13,d_plat,$C$4,d_type,$C$7,d_ind,$C$5,d_ctry,$C$6) -> 162842 | D23: =SUMIFS(d_conv,d_date,">="&$B$14,d_date,"<="&$B$15,d_plat,$C$4,d_type,$C$7,d_ind,$C$5,d_ctry,$C$6) -> 163970 | E23: =IF($B$16=1,IF(D23=0,"n/a",C23/D23-1),"n/a") -> -0.0068793072 | F23: =IF(ISNUMBER(E23),IF(E23>=0,1,-1),0) -> -1
A24: Impressions | B24: =SUMIFS(d_imp,d_date,">="&$B$9,d_date,"<="&$B$10,d_plat,$C$4,d_type,$C$7,d_ind,$C$5,d_ctry,$C$6) -> 185254234 | C24: =SUMIFS(d_imp,d_date,">="&$B$12,d_date,"<="&$B$13,d_plat,$C$4,d_type,$C$7,d_ind,$C$5,d_ctry,$C$6) -> 90938672 | D24: =SUMIFS(d_imp,d_date,">="&$B$14,d_date,"<="&$B$15,d_plat,$C$4,d_type,$C$7,d_ind,$C$5,d_ctry,$C$6) -> 94315562 | E24: =IF($B$16=1,IF(D24=0,"n/a",C24/D24-1),"n/a") -> -0.035804166 | F24: =IF(ISNUMBER(E24),IF(E24>=0,1,-1),0) -> -1
A25: Clicks | B25: =SUMIFS(d_clk,d_date,">="&$B$9,d_date,"<="&$B$10,d_plat,$C$4,d_type,$C$7,d_ind,$C$5,d_ctry,$C$6) -> 7132816 | C25: =SUMIFS(d_clk,d_date,">="&$B$12,d_date,"<="&$B$13,d_plat,$C$4,d_type,$C$7,d_ind,$C$5,d_ctry,$C$6) -> 3540871 | D25: =SUMIFS(d_clk,d_date,">="&$B$14,d_date,"<="&$B$15,d_plat,$C$4,d_type,$C$7,d_ind,$C$5,d_ctry,$C$6) -> 3591945 | E25: =IF($B$16=1,IF(D25=0,"n/a",C25/D25-1),"n/a") -> -0.014219037 | F25: =IF(ISNUMBER(E25),IF(E25>=0,1,-1),0) -> -1
A26: ROAS | B26: =IFERROR(B22/B21,0) -> 4.8775366 | C26: =IFERROR(C22/C21,0) -> 4.9414862 | D26: =IFERROR(D22/D21,0) -> 4.8153645 | E26: =IF($B$16=1,IF(D26=0,"n/a",C26/D26-1),"n/a") -> 0.026191528 | F26: =IF(ISNUMBER(E26),IF(E26>=0,1,-1),0) -> 1
A27: CPA | B27: =IFERROR(B21/B23,0) -> 33.991252 | C27: =IFERROR(C21/C23,0) -> 33.628287 | D27: =IFERROR(D21/D23,0) -> 34.351721 | E27: =IF($B$16=1,IF(D27=0,"n/a",C27/D27-1),"n/a") -> -0.021059609 | F27: =IF(ISNUMBER(E27),IF(E27<=0,1,-1),0) -> 1
A28: CTR | B28: =IFERROR(B25/B24,0) -> 0.03850285 | C28: =IFERROR(C25/C24,0) -> 0.038936911 | D28: =IFERROR(D25/D24,0) -> 0.03808433 | E28: =IF($B$16=1,IF(D28=0,"n/a",C28/D28-1),"n/a") -> 0.022386664 | F28: =IF(ISNUMBER(E28),IF(E28>=0,1,-1),0) -> 1
A29: CPC | B29: =IFERROR(B21/B25,0) -> 1.5574142 | C29: =IFERROR(C21/C25,0) -> 1.5465397 | D29: =IFERROR(D21/D25,0) -> 1.5681342 | E29: =IF($B$16=1,IF(D29=0,"n/a",C29/D29-1),"n/a") -> -0.013770811 | F29: =IF(ISNUMBER(E29),IF(E29>=0,1,-1),0) -> -1
A30: Conversion Rate | B30: =IFERROR(B23/B25,0) -> 0.045818089 | C30: =IFERROR(C23/C25,0) -> 0.04598925 | D30: =IFERROR(D23/D25,0) -> 0.045649363 | E30: =IF($B$16=1,IF(D30=0,"n/a",C30/D30-1),"n/a") -> 0.0074455994 | F30: =IF(ISNUMBER(E30),IF(E30>=0,1,-1),0) -> 1
A33: Platform | B33: Ad Spend | C33: Revenue | D33: Conversions | E33: ROAS | F33: CPA | G33: ROAS (max helper) | H33: ROAS (min helper)
A34: Google Ads | B34: =SUMIFS(d_spend,d_date,">="&$B$9,d_date,"<="&$B$10,d_plat,$C$4,d_type,$C$7,d_ind,$C$5,d_ctry,$C$6,d_plat,$A34) -> 6349268.9 | C34: =SUMIFS(d_rev,d_date,">="&$B$9,d_date,"<="&$B$10,d_plat,$C$4,d_type,$C$7,d_ind,$C$5,d_ctry,$C$6,d_plat,$A34) -> 22033745 | D34: =SUMIFS(d_conv,d_date,">="&$B$9,d_date,"<="&$B$10,d_plat,$C$4,d_type,$C$7,d_ind,$C$5,d_ctry,$C$6,d_plat,$A34) -> 131098 | E34: =IFERROR(C34/B34,0) -> 3.4702806 | F34: =IFERROR(B34/D34,0) -> 48.43147 | G34: =IF(B34>0,E34,-1) -> 3.4702806 | H34: =IF(B34>0,E34,9999) -> 3.4702806
A35: Meta Ads | B35: =SUMIFS(d_spend,d_date,">="&$B$9,d_date,"<="&$B$10,d_plat,$C$4,d_type,$C$7,d_ind,$C$5,d_ctry,$C$6,d_plat,$A35) -> 2106061.7 | C35: =SUMIFS(d_rev,d_date,">="&$B$9,d_date,"<="&$B$10,d_plat,$C$4,d_type,$C$7,d_ind,$C$5,d_ctry,$C$6,d_plat,$A35) -> 11926046 | D35: =SUMIFS(d_conv,d_date,">="&$B$9,d_date,"<="&$B$10,d_plat,$C$4,d_type,$C$7,d_ind,$C$5,d_ctry,$C$6,d_plat,$A35) -> 73262 | E35: =IFERROR(C35/B35,0) -> 5.6627239 | F35: =IFERROR(B35/D35,0) -> 28.746986 | G35: =IF(B35>0,E35,-1) -> 5.6627239 | H35: =IF(B35>0,E35,9999) -> 5.6627239
A36: TikTok Ads | B36: =SUMIFS(d_spend,d_date,">="&$B$9,d_date,"<="&$B$10,d_plat,$C$4,d_type,$C$7,d_ind,$C$5,d_ctry,$C$6,d_plat,$A36) -> 2653418.5 | C36: =SUMIFS(d_rev,d_date,">="&$B$9,d_date,"<="&$B$10,d_plat,$C$4,d_type,$C$7,d_ind,$C$5,d_ctry,$C$6,d_plat,$A36) -> 20223540 | D36: =SUMIFS(d_conv,d_date,">="&$B$9,d_date,"<="&$B$10,d_plat,$C$4,d_type,$C$7,d_ind,$C$5,d_ctry,$C$6,d_plat,$A36) -> 122452 | E36: =IFERROR(C36/B36,0) -> 7.6216925 | F36: =IFERROR(B36/D36,0) -> 21.66905 | G36: =IF(B36>0,E36,-1) -> 7.6216925 | H36: =IF(B36>0,E36,9999) -> 7.6216925
A37: Platforms in view | B37: =COUNTIF(B34:B36,">0") -> 3
A38: Best ROAS platform | B38: =INDEX($A$34:$A$36,MATCH(MAX(G34:G36),G34:G36,0)) -> TikTok Ads | C38: =MAX(G34:G36) -> 7.6216925
A39: Weakest ROAS platform | B39: =INDEX($A$34:$A$36,MATCH(MIN(H34:H36),H34:H36,0)) -> Google Ads | C39: =MIN(H34:H36) -> 3.4702806
A42: Industry | B42: Ad Spend | C42: Revenue | D42: ROAS | E42: Sort key | G42: Rank | H42: Key | I42: Index | J42: Sorted name | K42: Sorted ROAS
A43: E-commerce | B43: =SUMIFS(d_spend,d_date,">="&$B$9,d_date,"<="&$B$10,d_plat,$C$4,d_type,$C$7,d_ind,$C$5,d_ctry,$C$6,d_ind,$A43) -> 1923987.1 | C43: =SUMIFS(d_rev,d_date,">="&$B$9,d_date,"<="&$B$10,d_plat,$C$4,d_type,$C$7,d_ind,$C$5,d_ctry,$C$6,d_ind,$A43) -> 9637279.7 | D43: =IFERROR(C43/B43,0) -> 5.0090148 | E43: =D43+ROW()*0.000000001 -> 5.0090148 | G43: 1 | H43: =LARGE($E$43:$E$47,G43) -> 5.0441907 | I43: =MATCH(H43,$E$43:$E$47,0) -> 5 | J43: =INDEX($A$43:$A$47,I43) -> SaaS | K43: =INDEX($D$43:$D$47,I43) -> 5.0441907
A44: EdTech | B44: =SUMIFS(d_spend,d_date,">="&$B$9,d_date,"<="&$B$10,d_plat,$C$4,d_type,$C$7,d_ind,$C$5,d_ctry,$C$6,d_ind,$A44) -> 2296978.5 | C44: =SUMIFS(d_rev,d_date,">="&$B$9,d_date,"<="&$B$10,d_plat,$C$4,d_type,$C$7,d_ind,$C$5,d_ctry,$C$6,d_ind,$A44) -> 11549934 | D44: =IFERROR(C44/B44,0) -> 5.0283163 | E44: =D44+ROW()*0.000000001 -> 5.0283163 | G44: 2 | H44: =LARGE($E$43:$E$47,G44) -> 5.0283163 | I44: =MATCH(H44,$E$43:$E$47,0) -> 2 | J44: =INDEX($A$43:$A$47,I44) -> EdTech | K44: =INDEX($D$43:$D$47,I44) -> 5.0283163
A45: Fintech | B45: =SUMIFS(d_spend,d_date,">="&$B$9,d_date,"<="&$B$10,d_plat,$C$4,d_type,$C$7,d_ind,$C$5,d_ctry,$C$6,d_ind,$A45) -> 2271537.7 | C45: =SUMIFS(d_rev,d_date,">="&$B$9,d_date,"<="&$B$10,d_plat,$C$4,d_type,$C$7,d_ind,$C$5,d_ctry,$C$6,d_ind,$A45) -> 10173311 | D45: =IFERROR(C45/B45,0) -> 4.478601 | E45: =D45+ROW()*0.000000001 -> 4.4786011 | G45: 3 | H45: =LARGE($E$43:$E$47,G45) -> 5.0090148 | I45: =MATCH(H45,$E$43:$E$47,0) -> 1 | J45: =INDEX($A$43:$A$47,I45) -> E-commerce | K45: =INDEX($D$43:$D$47,I45) -> 5.0090148
A46: Healthcare | B46: =SUMIFS(d_spend,d_date,">="&$B$9,d_date,"<="&$B$10,d_plat,$C$4,d_type,$C$7,d_ind,$C$5,d_ctry,$C$6,d_ind,$A46) -> 2258683.9 | C46: =SUMIFS(d_rev,d_date,">="&$B$9,d_date,"<="&$B$10,d_plat,$C$4,d_type,$C$7,d_ind,$C$5,d_ctry,$C$6,d_ind,$A46) -> 10930814 | D46: =IFERROR(C46/B46,0) -> 4.8394616 | E46: =D46+ROW()*0.000000001 -> 4.8394616 | G46: 4 | H46: =LARGE($E$43:$E$47,G46) -> 4.8394616 | I46: =MATCH(H46,$E$43:$E$47,0) -> 4 | J46: =INDEX($A$43:$A$47,I46) -> Healthcare | K46: =INDEX($D$43:$D$47,I46) -> 4.8394616
A47: SaaS | B47: =SUMIFS(d_spend,d_date,">="&$B$9,d_date,"<="&$B$10,d_plat,$C$4,d_type,$C$7,d_ind,$C$5,d_ctry,$C$6,d_ind,$A47) -> 2357561.8 | C47: =SUMIFS(d_rev,d_date,">="&$B$9,d_date,"<="&$B$10,d_plat,$C$4,d_type,$C$7,d_ind,$C$5,d_ctry,$C$6,d_ind,$A47) -> 11891991 | D47: =IFERROR(C47/B47,0) -> 5.0441907 | E47: =D47+ROW()*0.000000001 -> 5.0441907 | G47: 5 | H47: =LARGE($E$43:$E$47,G47) -> 4.4786011 | I47: =MATCH(H47,$E$43:$E$47,0) -> 3 | J47: =INDEX($A$43:$A$47,I47) -> Fintech | K47: =INDEX($D$43:$D$47,I47) -> 4.478601
...

Sheet Lists
A1: Year in data | B1: =YEAR(MIN(Data!A:A)) -> 2024 | D1: Dropdown source lists. If a new platform/industry/country/campaign type is added to Data, add it here and in the Calc tables.
A3: Date Range | B3: Start | C3: End | E3: Platform | G3: Industry | I3: Country | K3: Campaign Type | M3: Month
A4: All Periods | B4: =DATE($B$1,1,1) -> 45292 | C4: =DATE($B$1,12,31) -> 45657 | E4: All Platforms | G4: All Industries | I4: All Countries | K4: All Campaign Types | M4: Jan
A5: Q1 2024 | B5: =DATE($B$1,1,1) -> 45292 | C5: =EOMONTH(DATE($B$1,3,1),0) -> 45382 | E5: Google Ads | G5: E-commerce | I5: Australia | K5: Display | M5: Feb
A6: Q2 2024 | B6: =DATE($B$1,4,1) -> 45383 | C6: =EOMONTH(DATE($B$1,6,1),0) -> 45473 | E6: Meta Ads | G6: EdTech | I6: Canada | K6: Search | M6: Mar
A7: Q3 2024 | B7: =DATE($B$1,7,1) -> 45474 | C7: =EOMONTH(DATE($B$1,9,1),0) -> 45565 | E7: TikTok Ads | G7: Fintech | I7: Germany | K7: Shopping | M7: Apr
A8: Q4 2024 | B8: =DATE($B$1,10,1) -> 45566 | C8: =EOMONTH(DATE($B$1,12,1),0) -> 45657 | G8: Healthcare | I8: India | K8: Video | M8: May
A9: H1 2024 | B9: =DATE($B$1,1,1) -> 45292 | C9: =EOMONTH(DATE($B$1,6,1),0) -> 45473 | G9: SaaS | I9: UAE | M9: Jun
A10: H2 2024 | B10: =DATE($B$1,7,1) -> 45474 | C10: =EOMONTH(DATE($B$1,12,1),0) -> 45657 | I10: UK | M10: Jul
A11: Jan 2024 | B11: =DATE($B$1,1,1) -> 45292 | C11: =EOMONTH(DATE($B$1,1,1),0) -> 45322 | I11: USA | M11: Aug
A12: Feb 2024 | B12: =DATE($B$1,2,1) -> 45323 | C12: =EOMONTH(DATE($B$1,2,1),0) -> 45351 | M12: Sep
A13: Mar 2024 | B13: =DATE($B$1,3,1) -> 45352 | C13: =EOMONTH(DATE($B$1,3,1),0) -> 45382 | M13: Oct
A14: Apr 2024 | B14: =DATE($B$1,4,1) -> 45383 | C14: =EOMONTH(DATE($B$1,4,1),0) -> 45412 | M14: Nov
A15: May 2024 | B15: =DATE($B$1,5,1) -> 45413 | C15: =EOMONTH(DATE($B$1,5,1),0) -> 45443 | M15: Dec
A16: Jun 2024 | B16: =DATE($B$1,6,1) -> 45444 | C16: =EOMONTH(DATE($B$1,6,1),0) -> 45473
A17: Jul 2024 | B17: =DATE($B$1,7,1) -> 45474 | C17: =EOMONTH(DATE($B$1,7,1),0) -> 45504
A18: Aug 2024 | B18: =DATE($B$1,8,1) -> 45505 | C18: =EOMONTH(DATE($B$1,8,1),0) -> 45535
A19: Sep 2024 | B19: =DATE($B$1,9,1) -> 45536 | C19: =EOMONTH(DATE($B$1,9,1),0) -> 45565
A20: Oct 2024 | B20: =DATE($B$1,10,1) -> 45566 | C20: =EOMONTH(DATE($B$1,10,1),0) -> 45596
A21: Nov 2024 | B21: =DATE($B$1,11,1) -> 45597 | C21: =EOMONTH(DATE($B$1,11,1),0) -> 45626
A22: Dec 2024 | B22: =DATE($B$1,12,1) -> 45627 | C22: =EOMONTH(DATE($B$1,12,1),0) -> 45657
